Workbook

Sheet Logs
A1: Timestamp | B1: Log Message
A2: 46243.037 | B2: |=== [doGet] Request Received ===| Retrieved 1000 rows from 'Config' sheet. ✅ Processed dates: [31_07_2026, 04_08_2026, test]
A3: 46243.04 | B3: |=== [doPost] Request Received ===| Raw Payload: {"date":"test","group":"2C4","email":"abc@thapar.edu",,"rollNumber":"1025031041","serialNumber":"20"} ❌ Exception: SyntaxError: Expected double-quoted property name in JSON at position 54 (line 1 column 55)
A4: 46243.04 | B4: |=== [doPost] Request Received ===| Raw Payload: {"date":"test","group":"2C4","email":"abc@thapar.edu","rollNumber":"1025031041","serialNumber":"20"} Parsed Parameters -> Date: 'test', Group: '2C4', Email: 'abc@thapar.edu', Roll: '1025031041', Serial: 20 'MyGroups' last row: 274 ✅ Roll Number '1025031041' verified in MyGroups. Max serial limit for date 'test' and group '2C4': 79 Sheet 'test_2C4' does not exist. Creating new sheet... Copying from 'Template' sheet. Sheet 'test_2C4' last row: 1 ✅ Successfully appended attendance entry for Roll: 1025031041, Seat #20
A5: 46243.04 | B5: |=== [doPost] Request Received ===| Raw Payload: {"date":"test","group":"2C4","email":"abc@thapar.edu","rollNumber":"1025031041","serialNumber":"20"} Parsed Parameters -> Date: 'test', Group: '2C4', Email: 'abc@thapar.edu', Roll: '1025031041', Serial: 20 'MyGroups' last row: 274 ✅ Roll Number '1025031041' verified in MyGroups. Max serial limit for date 'test' and group '2C4': 79 Found existing sheet: 'test_2C4'. Sheet 'test_2C4' last row: 2 ⚠️ Conflict: Duplicate Roll Number detected (1025031041).
A6: 46243.041 | B6: |=== [doPost] Request Received ===| Raw Payload: {"date":"test","group":"2C4","email":"abc@thapar.edu","rollNumber":"1025031041","serialNumber":"21"} Parsed Parameters -> Date: 'test', Group: '2C4', Email: 'abc@thapar.edu', Roll: '1025031041', Serial: 21 'MyGroups' last row: 274 ✅ Roll Number '1025031041' verified in MyGroups. Max serial limit for date 'test' and group '2C4': 79 Found existing sheet: 'test_2C4'. Sheet 'test_2C4' last row: 2 ⚠️ Conflict: Duplicate Roll Number detected (1025031041).

Sheet FullStudentList
A1: ThaparEmailID | B1: Name | C1: Roll | D1: GmailID | E1: Class | F1: Is Duplicate | G1: ContactNo.
A2: cmahajan_be25@thapar.edu | B2: Chirag Mahajan | C2: 1025230045 | D2: Chiragdob15@gmail.com | E2: 2W13 | F2: No | G2: 7888949112
A3: ksharma7_be25@thapar.edu | B3: Karanveer Sharma | C3: 1025170506 | D3: Karenveersharma09@gmail.com | E3: 2Q42 | F3: No | G3: 7717669335
A4: aaarnav_be25@thapar.edu | B4: Aarnav Jaglan | C4: 1025030048 | D4: aaarnav_be25@thapar.edu | E4: 2C12 | F4: No | G4: 8950686179
A5: aaarushi_be25@thapar.edu | B5: Aarushi | C5: 1025030477 | D5: a98113148@gmail.com | E5: 2C35 | F5: No | G5: 9041155430
A6: aaaryan_be25@thapar.edu | B6: Aaryan | C6: 1025030941 | D6: aaryanchhabra18@gmail.com | E6: 2C72 | F6: No | G6: 8950392093
A7: aaasmi_be25@thapar.edu | B7: Aasmi | C7: 1025030324 | D7: aaasmi_be25@thapar.edu | E7: 2C24 | F7: No | G7: 8283026948
A8: aaastha1_be25@gmail.com | B8: Aastha | C8: 1025160051 | D8: yashudangi2008@gmail.com | E8: 2P12 | F8: No | G8: 8851119030
A9: aachint_be25@thapar.edu | B9: Arpeet Achint | C9: 1025170164 | D9: arpeetkaur613@gmail.com | E9: 2Q21 | F9: No | G9: 9888550480
A10: aaditya_be25@thapar.edu | B10: Aditya | C10: 1025170037 | D10: adityaa172007@gmail.com | E10: 2Q12 | F10: No
A11: Aaditya1_be25@thapar.edu | B11: Aditya | C11: 1025090111 | D11: vatsaditya2408@gmail.com | E11: 2I12 | F11: No | G11: 9671376488
A12: aagarwal_be25@thapar.edu | B12: Ayu Agarwal | C12: 1025030625 | D12: aagarwal9_be25@thapar.edu | E12: 2C45 | F12: No | G12: 6378816765
A13: aagarwal1_be25@thapar.edu | B13: Aadya Agarwal | C13: 1025030878 | D13: aadyaagarwal275@gmail.com | E13: 2C64 | F13: No | G13: 8865917688
A14: aagarwal10_be25@thapar.edu | B14: Aditya Agarwal | C14: 1025030690 | D14: 1adityaagarwal7@gmail.com | E14: 2C52 | F14: No | G14: 9286205862
A15: aagarwal11_be25@thapar.edu | B15: Aarav Agarwal | C15: 1025230005 | D15: aarav.agarw25@gmail.com | E15: 2W11 | F15: No | G15: 8956097975
A16: aagarwal2_be25@thapar.edu | B16: Aarav Agarwal | C16: 1025170068 | D16: aarav071203@gmail.com | E16: 2Q13 | F16: No | G16: 9319970025
A17: aagarwal3_be25@thapar.edu | B17: Aditya Agarwal | C17: 1025170063 | D17: adityaagarwal110408@gmail.com | E17: 2Q13 | F17: No | G17: 7982301911
A18: aagarwal4_be25@thapar.edu | B18: Akhil Agarwal | C18: 1025030012 | D18: akhil77agarwal@gmail.com | E18: 2C11 | F18: No | G18: 7060745392
A19: aagarwal5_be25@thapar.edu | B19: Anshika Agarwal | C19: 1025170253 | D19: anshikaagarwal2007@gmail.com | E19: 2Q24 | F19: No | G19: 9084699938
A20: aagarwal7_be25@thapar.edu | B20: Aditya Agarwal | C20: 1025170276 | D20: aditya.dpsgbn01@gmail.com | E20: 2Q25 | F20: No | G20: 9818700870
A21: aagarwal8_be25@thapar.edu | B21: Ananya Agarwal | C21: 1025030517 | D21: artistananya1@gmail.com | E21: 2C41 | F21: No | G21: 7489243681
A22: aaggarwal1_be25@thapar.edu | B22: Agaaz Aggarwal | C22: 1025030309 | D22: agaazaggarwal@gmail.com | E22: 2C23 | F22: No | G22: 8872032444
... A128: agoria_be25@thapar.edu | B128: Akshit Goria | C128: 1025030952 | D128: goriaakshit@gmail.com | E128: 2UNSW | F128: No | G128: 8273745264
A129: Agoyal_be25@thapar.edu | B129: Aditya Goyal | C129: 1025030569 | D129: adityaarushi2@gmail.com | E129: 2C43 | F129: No | G129: =+91 9501435950 -> #ERROR!
A130: agoyal10_be25@thapar.edu | B130: Abhimanyu Goyal | C130: 1025030945 | D130: mr.goyal231206@gmail.com | E130: 2C72 | F130: No | G130: 9844324000
A131: agoyal11_be25@thapar.edu | B131: Aditya Goyal | C131: 1025030100 | D131: adityagoyal1507@gmail.com | E131: 2C14 | F131: No | G131: 9990371000
A132: agoyal12_be25@thapar.edu | B132: Ananya Goyal | C132: 1025030717 | D132: goyalananya2411@gmail.com | E132: 2C53 | F132: No | G132: 7341179362
A133: agoyal14_be25@thapar.edu | B133: Aarushi Goyal | C133: 1025030869 | D133: goyalaarushi685@gmail.com | E133: 2C64 | F133: No | G133: 9417712199
A134: agoyal3_be25@thapar.edu | B134: Ashima Goyal | C134: 1025030296 | D134: ashimagoel922@gmail.com | E134: 2C23 | F134: No | G134: 7009557036
A135: Agoyal4_be25@thapar.edu | B135: Ayush Goyal | C135: 1025030001 | D135: Ayush.goyal0023@gmail.com | E135: 2C11 | F135: No | G135: 8872698500
A136: agoyal8_be25@thapar.edu | B136: Aishwarya Goyal | C136: 1025030149 | D136: aishwaryaaggoyal@gmail.com | E136: 2C16 | F136: No | G136: 8699644790
A137: agoyal9_be25@thapar.edu | B137: Aarav Goyal | C137: 1025170318 | D137: aaravgoyal2507@gmail.com | E137: 2Q31 | F137: No | G137: 7347622176
A138: agrover1_be25@thapar.edu | B138: Aditya Grover | C138: 1025170427 | D138: adityagrover0077@gmail.com | E138: 2Q35 | F138: No | G138: 7814206700
A139: agrover2_be25@thapar.edu | B139: Ayaan Grover | C139: 1025170377 | D139: Ayaangrover@icloud.com | E139: 2Q33 | F139: No | G139: 6284710438
A140: Agupta_be25@thapar.edu | B140: Angel Gupta | C140: 1025030966 | D140: a62105338@gmail.com | E140: 2C73 | F140: No
A141: agupta1_be25@thapar.edu | B141: Aadi Gupta | C141: 1025170129 | D141: aadigupta1712@gmail.com | E141: 2Q15 | F141: No | G141: 8279958435
A142: agupta10_be25@thapar.edu | B142: Armaan Gupta | C142: 1025090050 | D142: agupta10_be25@thapar.edu | E142: 2I12 | F142: No | G142: 9136321694
A143: agupta13_be25@thapar.edu | B143: Aryan Gupta | C143: 1025030996 | D143: aryangupta1608@gmail.com | E143: 2C74 | F143: No | G143: 9646203771
A144: agupta17_be25@thapar.edu | B144: Akshat Gupta | C144: 1025170217 | D144: gakshat387@gmail.com | E144: 2Q23 | F144: No | G144: 9170822752
A145: agupta2_be25@thapar.edu | B145: Aastha Gupta | C145: 1025160066 | D145: aasthasubod@gmail.com | E145: 2P11 | F145: No | G145: 9910788359
...

Sheet FullCCList
A1: User Id | B1: Name | C1: CC Username | D1: Email | E1: Roll No | F1: Class | G1: Division | H1: Additional Data | I1: Edit Student Data
A2: 6126995 | B2: Gurjot Kaur | C2: gurjot_kaur | D2: gkaur4_be25@thapar.edu | E2: 1025030205 | F2: 2C18 | I2: gurjot_kaur
A3: 6135704 | B3: Abhinav Prem Singh | C3: trip_glint_96 | D3: asingh6_be25@thapar.edu | E3: 1025030397 | F3: 2C32 | I3: trip_glint_96
A4: 6136255 | B4: Harshita Hooda | C4: yoke_dawn_47 | D4: hharshita1_be25@thapar.edu | E4: 1025030412 | F4: 2C33 | I4: yoke_dawn_47
A5: 6201130 | B5: Keshav Singla | C5: ksingla1_be25 | D5: ksingla1_be25@thapar.edu | E5: 1025030490 | F5: 2C35 | I5: ksingla1_be25
A6: 6225329 | B6: Priyanshi Singla | C6: glow_serene_01 | D6: psingla_be25@thapar.edu | E6: 1025170044 | F6: 2Q12 | I6: glow_serene_01
A7: 6231919 | B7: Hiya Kasturia | C7: hiya_kasturia | D7: hkasturia_be25@thapar.edu | E7: 1025170219 | F7: 2Q23 | I7: hiya_kasturia
A8: 6332264 | B8: Dakshdeep Kaur Kahlon | C8: daksh_kahlon | D8: dkahlon_be25@thapar.edu | E8: 1025030024 | F8: 2C11 | I8: daksh_kahlon
A9: 6419674 | B9: Krishna Garg | C9: uber_glint_93 | D9: kgarg2_be25@thapar.edu | E9: 1025160025 | F9: 2P11 | I9: uber_glint_93
A10: 6421109 | B10: Tavarit vashistha | C10: gaze_ref_38 | D10: ttavarit_be25@thapar.edu | E10: 1025030287 | F10: 2C23 | I10: gaze_ref_38
A11: 6545821 | B11: Sushant Gagneja | C11: calm_mules_36 | D11: sgagneja_be25@thapar.edu | E11: 1025030509 | F11: 2C41 | I11: calm_mules_36
A12: 6556777 | B12: Esha Vidhya Thalla | C12: adorn_crows_29 | D12: ethalla_be25@thapar.edu | E12: 1025030131 | F12: 2C15 | I12: adorn_crows_29
A13: 6671056 | B13: Sargun | C13: venue_frog_48 | D13: ssargun_be25@thapar.edu | E13: 1025160088 | F13: 2P13 | I13: venue_frog_48
... A1941: 7279057 | B1941: Dhruva Sharma | C1941: thapar_8583 | D1941: dsharma9_be25@thapar.edu | E1941: 1025230142 | F1941: 2W13 | I1941: thapar_8583

Sheet 2C7
A1: Roll No | B1: Name | C1: Group | D1: =MATCHING_SHEETS("2C7") -> #NAME?
A2: Total/MarkedAttendance | D2: {=BYCOL(D1:Z1, LAMBDA(col_header, IF(ISBLANK(col_header),, SUM(OFFSET(col_header, 2, 0, ROWS(A:A)-2)) & "/" & COUNTA(INDIRECT("'" & col_header & "'!$C$2:$C")) ) ))} -> 0/1
A3: 1025030913 | B3: ABHIJAY SINGH | C3: 2C71 | D3: {=IF(A3:A134="","",IF(COUNTIF(INDIRECT("'"&D$1&"'!$C:$C"),$A$3:$A134)>0,1,0))} -> 0 | E3: {=IF(B3:B134="","",IF(COUNTIF(INDIRECT("'"&E$1&"'!$C:$C"),$A$3:$A134)>0,1,0))} -> 0 | F3: {=IF(C3:C134="","",IF(COUNTIF(INDIRECT("'"&F$1&"'!$C:$C"),$A$3:$A134)>0,1,0))} -> 0 | G3: {=IF(D3:D134="","",IF(COUNTIF(INDIRECT("'"&G$1&"'!$C:$C"),$A$3:$A134)>0,1,0))} -> 0 | H3: {=IF(E3:E134="","",IF(COUNTIF(INDIRECT("'"&H$1&"'!$C:$C"),$A$3:$A134)>0,1,0))} -> 0
A4: 1025030920 | B4: VIRENDRA DHAKA | C4: 2C71 | D4: 0 | E4: 0 | F4: 0 | G4: 0 | H4: 0
A5: 1025030926 | B5: KISHLAY SINHA | C5: 2C71 | D5: 0 | E5: 0 | F5: 0 | G5: 0 | H5: 0
A6: 1025030914 | B6: AMITOJ SINGH | C6: 2C71 | D6: 0 | E6: 0 | F6: 0 | G6: 0 | H6: 0
A7: 1025031071 | B7: NIKIT SHRESTHA | C7: 2C71 | D7: 0 | E7: 0 | F7: 0 | G7: 0 | H7: 0
A8: 1025031074 | B8: SWIKAR DEVKOTA | C8: 2C71 | D8: 0 | E8: 0 | F8: 0 | G8: 0 | H8: 0
A9: 1025030923 | B9: ABHYUDAY SAKSENA | C9: 2C71 | D9: 0 | E9: 0 | F9: 0 | G9: 0 | H9: 0
A10: 1025031048 | B10: PARPREET | C10: 2C71 | D10: 0 | E10: 0 | F10: 0 | G10: 0 | H10: 0
A11: 1025030911 | B11: AMAN KUMAR | C11: 2C71 | D11: 0 | E11: 0 | F11: 0 | G11: 0 | H11: 0
A12: 1025030918 | B12: RISHABH BANSAL | C12: 2C71 | D12: 0 | E12: 0 | F12: 0 | G12: 0 | H12: 0
A13: 1025030925 | B13: MEHERANSH VAISH | C13: 2C71 | D13: 0 | E13: 0 | F13: 0 | G13: 0 | H13: 0
A14: 1025030988 | B14: ADITYA RAJ | C14: 2C71 | D14: 0 | E14: 0 | F14: 0 | G14: 0 | H14: 0
A15: 1025030922 | B15: GAUTAM GIROTRA | C15: 2C71 | D15: 0 | E15: 0 | F15: 0 | G15: 0 | H15: 0
... A134: 1025031017 | B134: ATHARAV SHARMA | C134: 2C75 | D134: 0 | E134: 0 | F134: 0 | G134: 0 | H134: 0

Sheet 2C4
A1: Roll No | B1: Name | C1: Group | D1: =MATCHING_SHEETS("2C4") -> #NAME? | E1: 04_08_2026_2C4 | F1: 05_08_2026_2C4
A2: Total/MarkedAttendance | D2: {=BYCOL(D1:Z1, LAMBDA(col_header, IF(ISBLANK(col_header),, SUM(OFFSET(col_header, 2, 0, ROWS(A:A)-2)) & "/" & COUNTA(INDIRECT("'" & col_header & "'!$C$2:$C")) ) ))} -> 0/1 | E2: 19/19 | F2: 0/1
A3: 1025030508 | B3: HITESH GUPTA | C3: 2C41 | D3: {=IF(A3:A1001="","",IF(COUNTIF(INDIRECT("'"&D$1&"'!$C:$C"),$A$3:$A1001)>0,1,0))} -> 0 | E3: {=IF(B3:B1001="","",IF(COUNTIF(INDIRECT("'"&E$1&"'!$C:$C"),$A$3:$A1001)>0,1,0))} -> 0 | F3: {=IF(C3:C1001="","",IF(COUNTIF(INDIRECT("'"&F$1&"'!$C:$C"),$A$3:$A1001)>0,1,0))} -> 0
A4: 1025030525 | B4: AGAMYA PANDEY | C4: 2C41 | D4: 0 | E4: 0 | F4: 0
A5: 1025030515 | B5: NISHITA GUPTA | C5: 2C41 | D5: 0 | E5: 0 | F5: 0
A6: 1025030520 | B6: AKSHATA | C6: 2C41 | D6: 0 | E6: 0 | F6: 0
A7: 1025030500 | B7: PALKIN GUPTA | C7: 2C41 | D7: 0 | E7: 0 | F7: 0
A8: 1025030512 | B8: USTAT SINGH BHARARA | C8: 2C41 | D8: 0 | E8: 0 | F8: 0
A9: 1025030518 | B9: KYRA AGRAWAL | C9: 2C41 | D9: 0 | E9: 0 | F9: 0
A10: 1025030501 | B10: SIDDHARTHA KUMAR | C10: 2C41 | D10: 0 | E10: 0 | F10: 0
A11: 1025030516 | B11: AGRIMA TIWARI | C11: 2C41 | D11: 0 | E11: 0 | F11: 0
A12: 1025030509 | B12: SUSHANT GAGNEJA | C12: 2C41 | D12: 0 | E12: 0 | F12: 0
A13: 1025030517 | B13: ANANYA AGARWAL | C13: 2C41 | D13: 0 | E13: 0 | F13: 0
A14: 1025030504 | B14: VANSH SINGAL | C14: 2C41 | D14: 0 | E14: 0 | F14: 0
A15: 1025030513 | B15: SAMARTHA GURTU | C15: 2C41 | D15: 0 | E15: 0 | F15: 0
... A139: 1025030613 | B139: ARCHIT JHA | C139: 2C45 | D139: 0 | E139: 0 | F139: 0

Sheet Defaulters_2C7
A1: Roll No | B1: Name | C1: Group | D1: =MATCHING_SHEETS("2C7") -> #NAME? | E1: 03_08_2026_2C7 | F1: 31_07_2026_2C7 | G1: 06_08_2026_2C7 | H1: 07_08_2026_2C7
A2: NotFound/TotalSubmission | D2: {=BYCOL(D1:Z1, LAMBDA(col_header, IF(ISBLANK(col_header),, COUNTA(OFFSET(col_header, 2, 0, 158)) & "/" & COUNTA(INDIRECT("'" & col_header & "'!$C$2:$C")) ) ))} -> 1/1 | E2: 1/1 | F2: 1/42 | G2: 1/1 | H2: 1/1
A3: 1025030913 | B3: ABHIJAY SINGH | C3: 2C71 | D3: =IFERROR(__xludf.DUMMYFUNCTION("LET( list,INDIRECT(""'""&D$1&""'!$C$2:$C$160""), FILTER(list,BYROW(list,LAMBDA(x,COUNTIF($A$3:$A$160,x)=0))) )"),"#NAME?") -> #NAME? | E3: =IFERROR(__xludf.DUMMYFUNCTION("LET( list,INDIRECT(""'""&E$1&""'!$C$2:$C$160""), FILTER(list,BYROW(list,LAMBDA(x,COUNTIF($A$3:$A$160,x)=0))) )"),"#REF!") -> #REF! | F3: =IFERROR(__xludf.DUMMYFUNCTION("LET( list,INDIRECT(""'""&F$1&""'!$C$2:$C$160""), FILTER(list,BYROW(list,LAMBDA(x,COUNTIF($A$3:$A$160,x)=0))) )"),"") | G3: =IFERROR(__xludf.DUMMYFUNCTION("LET( list,INDIRECT(""'""&G$1&""'!$C$2:$C$160""), FILTER(list,BYROW(list,LAMBDA(x,COUNTIF($A$3:$A$160,x)=0))) )"),"#REF!") -> #REF! | H3: =IFERROR(__xludf.DUMMYFUNCTION("LET( list,INDIRECT(""'""&H$1&""'!$C$2:$C$160""), FILTER(list,BYROW(list,LAMBDA(x,COUNTIF($A$3:$A$160,x)=0))) )"),"#REF!") -> #REF!
A4: 1025030920 | B4: VIRENDRA DHAKA | C4: 2C71 | F4: =IFERROR(__xludf.DUMMYFUNCTION("""COMPUTED_VALUE"""),1.025030966E9) -> 1025030966
A5: 1025030926 | B5: KISHLAY SINHA | C5: 2C71
A6: 1025030914 | B6: AMITOJ SINGH | C6: 2C71
A7: 1025031071 | B7: NIKIT SHRESTHA | C7: 2C71
A8: 1025031074 | B8: SWIKAR DEVKOTA | C8: 2C71
A9: 1025030923 | B9: ABHYUDAY SAKSENA | C9: 2C71
A10: 1025031048 | B10: PARPREET | C10: 2C71
A11: 1025030911 | B11: AMAN KUMAR | C11: 2C71
A12: 1025030918 | B12: RISHABH BANSAL | C12: 2C71
A13: 1025030925 | B13: MEHERANSH VAISH | C13: 2C71
A14: 1025030988 | B14: ADITYA RAJ | C14: 2C71
A15: 1025030922 | B15: GAUTAM GIROTRA | C15: 2C71
A16: 1025030921 | B16: ARJUN MALHOTRA | C16: 2C71
... A134: 1025031017 | B134: ATHARAV SHARMA | C134: 2C75

Sheet Defaulters_2C4
A1: Roll No | B1: Name | C1: Group | D1: =MATCHING_SHEETS("2C4") -> #NAME? | E1: 04_08_2026_2C4 | F1: 05_08_2026_2C4
A2: NotFound/TotalSubmission | D2: {=BYCOL(D1:Z1, LAMBDA(col_header, IF(ISBLANK(col_header),, COUNTA(OFFSET(col_header, 2, 0, 158)) & "/" & COUNTA(INDIRECT("'" & col_header & "'!$C$2:$C")) ) ))} -> 1/1 | E2: 0/19 | F2: 1/1
A3: 1025030508 | B3: HITESH GUPTA | C3: 2C41 | D3: =IFERROR(__xludf.DUMMYFUNCTION("LET( list,INDIRECT(""'""&D$1&""'!$C$2:$C$160""), FILTER( list, BYROW(list,LAMBDA(x, (COUNTIF($A$3:$A$160,x)=0)+(COUNTIF(list,x)>1) )) ) )"),"#NAME?") -> #NAME? | E3: =IFERROR(__xludf.DUMMYFUNCTION("LET( list,INDIRECT(""'""&E$1&""'!$C$2:$C$160""), FILTER(list,BYROW(list,LAMBDA(x,COUNTIF($A$3:$A$160,x)=0))) )"),"") | F3: =IFERROR(__xludf.DUMMYFUNCTION("LET( list,INDIRECT(""'""&F$1&""'!$C$2:$C$160""), FILTER(list,BYROW(list,LAMBDA(x,COUNTIF($A$3:$A$160,x)=0))) )"),"#REF!") -> #REF!
A4: 1025030525 | B4: AGAMYA PANDEY | C4: 2C41
A5: 1025030515 | B5: NISHITA GUPTA | C5: 2C41
A6: 1025030520 | B6: AKSHATA | C6: 2C41
A7: 1025030500 | B7: PALKIN GUPTA | C7: 2C41
A8: 1025030512 | B8: USTAT SINGH BHARARA | C8: 2C41
A9: 1025030518 | B9: KYRA AGRAWAL | C9: 2C41
A10: 1025030501 | B10: SIDDHARTHA KUMAR | C10: 2C41
A11: 1025030516 | B11: AGRIMA TIWARI | C11: 2C41
A12: 1025030509 | B12: SUSHANT GAGNEJA | C12: 2C41
A13: 1025030517 | B13: ANANYA AGARWAL | C13: 2C41
A14: 1025030504 | B14: VANSH SINGAL | C14: 2C41
A15: 1025030513 | B15: SAMARTHA GURTU | C15: 2C41
... A139: 1025030613 | B139: ARCHIT JHA | C139: 2C45

Sheet MyGroups
A1: User Id | B1: Name | C1: CC Username | D1: Email | E1: Roll No | F1: Class | G1: GmailID | H1: ContactDetails | I1: CodeChefID
A2: 6545821 | B2: Sushant Gagneja | C2: calm_mules_36 | D2: sgagneja_be25@thapar.edu | E2: 1025030509 | F2: 2C41 | G2: {=XLOOKUP(E2,FullStudentList!C:C,FullStudentList!D:D)} -> MLnerdfinalboss@gmail.com | H2: {=XLOOKUP(E2,FullStudentList!C:C,FullStudentList!G:G)} -> 6280811057 | I2: calm_mules_36
A3: 6714735 | B3: Ayush Singla | C3: jolly_mules_60 | D3: asingla7_be25@thapar.edu | E3: 1025030492 | F3: 2C41 | G3: {=XLOOKUP(E3,FullStudentList!C:C,FullStudentList!D:D)} -> ayushsingla206@gmail.com | H3: {=XLOOKUP(E3,FullStudentList!C:C,FullStudentList!G:G)} -> 6239319621 | I3: jolly_mules_60
A4: 6714860 | B4: Rohan Kumar Gogar | C4: quick_zone_88 | D4: rgogar_be25@thapar.edu | E4: 1025030704 | F4: 2C44 | G4: {=XLOOKUP(E4,FullStudentList!C:C,FullStudentList!D:D)} -> rohangogar2020@gmail.com | H4: {=XLOOKUP(E4,FullStudentList!C:C,FullStudentList!G:G)} -> 8595791148 | I4: quick_zone_88
A5: 6772027 | B5: Diya Handa | C5: gold_goal_35 | D5: dhanda_be25@thapar.edu | E5: 1025030560 | F5: 2C43 | G5: {=XLOOKUP(E5,FullStudentList!C:C,FullStudentList!D:D)} -> diya. handa2006@gmail.com | H5: {=XLOOKUP(E5,FullStudentList!C:C,FullStudentList!G:G)} -> 9463050218 | I5: gold_goal_35
A6: 6811784 | B6: Nikit Shrestha | C6: nikitxstha | D6: nshrestha_be25@thapar.edu | E6: 1025031071 | F6: 2C71 | G6: {=XLOOKUP(E6,FullStudentList!C:C,FullStudentList!D:D)} -> nikitxstha@gmail.com | H6: {=XLOOKUP(E6,FullStudentList!C:C,FullStudentList!G:G)} -> 9872423375 | I6: nikitxstha
A7: 7081514 | B7: Akshay Kumar Pandey | C7: parade_boar_54 | D7: apandey1_be25@thapar.edu | E7: 1025030636 | F7: 2C45 | G7: {=XLOOKUP(E7,FullStudentList!C:C,FullStudentList!D:D)} -> akshayom51@gmail.com | H7: {=XLOOKUP(E7,FullStudentList!C:C,FullStudentList!G:G)} -> 9892535043 | I7: parade_boar_54
A8: 7232209 | B8: Aryan Verma | C8: next_rustle_74 | D8: averma7_be25@thapar.edu | E8: 1025030092 | F8: 2C44 | G8: {=XLOOKUP(E8,FullStudentList!C:C,FullStudentList!D:D)} -> Aryan.verma5947@thapar.edu | H8: {=XLOOKUP(E8,FullStudentList!C:C,FullStudentList!G:G)} -> 9801484029 | I8: next_rustle_74
A9: 7243464 | B9: Chaitanya Sharma | C9: bright_dust_51 | D9: csharma1_be25@thapar.edu | E9: 1025030584 | F9: 2C43 | G9: {=XLOOKUP(E9,FullStudentList!C:C,FullStudentList!D:D)} -> chaitanyasharmasdd@gmail.com | H9: {=XLOOKUP(E9,FullStudentList!C:C,FullStudentList!G:G)} -> 9779088605 | I9: bright_dust_51
A10: 7247431 | B10: Swikar Devkota | C10: swiks_dev | D10: sdevkota_be25@thapar.edu | E10: 1025031074 | F10: 2C71 | G10: {=XLOOKUP(E10,FullStudentList!C:C,FullStudentList!D:D)} -> swikar000@gmail.com | H10: {=XLOOKUP(E10,FullStudentList!C:C,FullStudentList!G:G)} -> 9769192559 | I10: swiks_dev
A11: 7248692 | B11: Aryaman Tripathi | C11: dandy_tomb_14 | D11: atripathi1_be25@thapar.edu | E11: 1025031089 | F11: 2C45 | G11: {=XLOOKUP(E11,FullStudentList!C:C,FullStudentList!D:D)} -> ptatat0211@gmail.com | H11: {=XLOOKUP(E11,FullStudentList!C:C,FullStudentList!G:G)} -> 8284099303 | I11: dandy_tomb_14
A12: 7257627 | B12: Samay Garg | C12: sgarg_be25 | D12: sgarg6_be25@thapar.edu | E12: 1025030592 | F12: 2C44 | G12: {=XLOOKUP(E12,FullStudentList!C:C,FullStudentList!D:D)} -> samay9g@gmail.com | H12: {=XLOOKUP(E12,FullStudentList!C:C,FullStudentList!G:G)} -> 7986574788 | I12: sgarg_be25
A13: 7257882 | B13: Hemakshi Grover | C13: epic_harbor_92 | D13: hgrover_be25@thapar.edu | E13: 1025030522 | F13: 2C41 | G13: {=XLOOKUP(E13,FullStudentList!C:C,FullStudentList!D:D)} -> groverhemakshi@gmail.com | H13: {=XLOOKUP(E13,FullStudentList!C:C,FullStudentList!G:G)} -> 9289050223 | I13: epic_harbor_92
... A271: 7267844 | B271: HARSH PREMCHANDANI | C271: thapar_9737 | D271: hpremchandani_be25@thapar.edu | E271: 1025030596 | F271: 2C44 | G271: {=XLOOKUP(E271,FullStudentList!C:C,FullStudentList!D:D)} -> harshpremchandani02@gmail.com | H271: {=XLOOKUP(E271,FullStudentList!C:C,FullStudentList!G:G)} -> #ERROR! | I271: thapar_9737
G272: {=XLOOKUP(E272,FullStudentList!C:C,FullStudentList!D:D)} -> #N/A
G273: {=XLOOKUP(E273,FullStudentList!C:C,FullStudentList!D:D)} -> #N/A
G274: {=XLOOKUP(E274,FullStudentList!C:C,FullStudentList!D:D)} -> #N/A

Sheet Config
B1: ATTENDANCE_URL | C1: https://subhrendu1987.github.io/course/attendance/
A2: Date | B2: Group | C2: ImageUrl | D2: MaxSerial
A3: 31_07_2026 | B3: 2C7 | C3: =IFERROR(__xludf.DUMMYFUNCTION("ARRAYFORMULA(IF((A3:A1000<>"""")*(B3:B1000<>""""), ""https://raw.githubusercontent.com/""& INDEX(REGEXEXTRACT($C$1,""https://([^./]+)\.github\.io/([^/]+)""),1,1)&""/""& INDEX(REGEXEXTRACT($C$1,""https://([^./]+)\.github\.io/([^/]+)""),1,2)& ""/main/at"&"tendance/Dataset/Preview/""& A3:A1000&""_""&B3:B1000&"".jpg"", """"))"),"https://raw.githubusercontent.com/subhrendu1987/course/main/attendance/Dataset/Preview/31_07_2026_2C7.jpg") -> https://raw.githubusercontent.com/subhrendu1987/course/main/attendance/Dataset/Preview/31_07_2026_2C7.jpg | D3: 92
A4: 04_08_2026 | B4: 2C4 | C4: =IFERROR(__xludf.DUMMYFUNCTION("""COMPUTED_VALUE"""),"https://raw.githubusercontent.com/subhrendu1987/course/main/attendance/Dataset/Preview/04_08_2026_2C4.jpg") -> https://raw.githubusercontent.com/subhrendu1987/course/main/attendance/Dataset/Preview/04_08_2026_2C4.jpg | D4: 23
A5: test | B5: 2C4 | C5: =IFERROR(__xludf.DUMMYFUNCTION("""COMPUTED_VALUE"""),"https://raw.githubusercontent.com/subhrendu1987/course/main/attendance/Dataset/Preview/test_2C4.jpg") -> https://raw.githubusercontent.com/subhrendu1987/course/main/attendance/Dataset/Preview/test_2C4.jpg | D5: 79
C6: =IFERROR(__xludf.DUMMYFUNCTION("""COMPUTED_VALUE"""),"")
C7: =IFERROR(__xludf.DUMMYFUNCTION("""COMPUTED_VALUE"""),"")
C8: =IFERROR(__xludf.DUMMYFUNCTION("""COMPUTED_VALUE"""),"")
C9: =IFERROR(__xludf.DUMMYFUNCTION("""COMPUTED_VALUE"""),"")
C10: =IFERROR(__xludf.DUMMYFUNCTION("""COMPUTED_VALUE"""),"")
C11: =IFERROR(__xludf.DUMMYFUNCTION("""COMPUTED_VALUE"""),"")
C12: =IFERROR(__xludf.DUMMYFUNCTION("""COMPUTED_VALUE"""),"")
C13: =IFERROR(__xludf.DUMMYFUNCTION("""COMPUTED_VALUE"""),"")
C14: =IFERROR(__xludf.DUMMYFUNCTION("""COMPUTED_VALUE"""),"")
C15: =IFERROR(__xludf.DUMMYFUNCTION("""COMPUTED_VALUE"""),"")
C16: =IFERROR(__xludf.DUMMYFUNCTION("""COMPUTED_VALUE"""),"")
C17: =IFERROR(__xludf.DUMMYFUNCTION("""COMPUTED_VALUE"""),"")
... C1000: =IFERROR(__xludf.DUMMYFUNCTION("""COMPUTED_VALUE"""),"")

Sheet Template
A1: Timestamp | B1: Email | C1: Roll Number | D1: Serial Number

Sheet 04_08_2026_2C4
A1: Timestamp | B1: Email | C1: Roll Number | D1: Serial Number
A2: 46238.777 | B2: bgoyal_be25@thapar.edu | C2: 1025030521 | D2: 19
A3: 46238.782 | B3: rsingla1_be25@thapar.edu | C3: 1025030587 | D3: 2
A4: 46238.782 | B4: skumar1_be25@thapar.edu | C4: 1025030606 | D4: 14
A5: 46238.783 | B5: htrivedi1_be25@thapar.edu | C5: 1025030582 | D5: 1
A6: 46238.784 | B6: cchirag_be25@thapar.edu | C6: 1025030571 | D6: 17
A7: 46238.785 | B7: kgoyal2_be25@thapar.edu | C7: 1025030610 | D7: 4
A8: 46238.789 | B8: kkaur4_be25@thapar.edu | C8: 1025030561 | D8: 11
A9: 46238.802 | B9: sghosh2_be25@thapar.edu | C9: 1025030549 | D9: 3
A10: 46238.806 | B10: asingla7_be25@thapar.edu | C10: 1025030492 | D10: 20
A11: 46238.813 | B11: daggarwal2_be25@thapar.edu | C11: 1025030566 | D11: 18
A12: 46238.823 | B12: psrivastava1_be25@thapar.edu | C12: 1025030601 | D12: 9
A13: 46238.824 | B13: rroshni_be25@thapar.edu | C13: 1025030598 | D13: 10
... A20: 46241.812 | B20: vjaiswal_be25@thapar.edu | C20: 1025030621 | D20: 12

Sheet 31_07_2026_2C7
A1: Timestamp | B1: Email | C1: Roll Number | D1: Serial Number
A2: 46240.841 | B2: djain3_be25@thapar.edu | C2: 1025031001 | D2: 67
A3: 46240.845 | B3: jmahajan_be25@thapar.edu | C3: 1025031041 | D3: 41
A4: 46240.845 | B4: vbahuguna_be25@thapar.edu | C4: 1025030955 | D4: 12
A5: 46240.846 | B5: vnagpal_be25@thapar.edu | C5: 1025031037 | D5: 21
A6: 46240.846 | B6: adhaliwal_be25@thapar.edu | C6: 1025031034 | D6: 32
A7: 46240.848 | B7: hharshmitha_be25@thapar.edu | C7: 1025030948 | D7: 56
A8: 46240.848 | B8: agupta9_be25@thapar.edu | C8: 1025030999 | D8: 20
A9: 46240.85 | B9: hpriya_be25@thapar.edu | C9: 1025030971 | D9: 33
A10: 46240.85 | B10: hgoyal2_be25@thapar.edu | C10: 1025030970 | D10: 17
A11: 46240.851 | B11: nmangla1_be25@thapar.edu | C11: 1025031077 | D11: 36
A12: 46240.851 | B12: ykalra_be25@thapar.edu | C12: 1025030937 | D12: 85
A13: 46240.853 | B13: dagarwal1_be25@thapar.edu | C13: 1025030981 | D13: 49
... A44: 46243.021 | B44: ssejal1_be25@thapar.edu | C44: 1025030997 | D44: 51

Sheet test_2C4
A1: Timestamp | B1: Email | C1: Roll Number | D1: Serial Number
A2: 46243.04 | B2: abc@thapar.edu | C2: 1025031041 | D2: 20
